Workbook

Sheet Sheet1
AS22: 0 | AW22: 1
AR25: 10 | AU25: 14 | AX25: 11
AP26: 7 | AZ26: 2
AR30: 8 | AX30: 9
AP34: 6 | AZ34: 3
AR35: 12 | AU35: 15 | AX35: 13
AS38: 5 | AW38: 4

Sheet menu mockup
P63: x | Q63: y | S63: x in 10bit bin | X63: y in 9bit bin
O64: gauss | P64: 320 | Q64: 352 | S64: 0101000000 | X64: 101100000
O65: median | P65: 394 | Q65: 352 | S65: 0110001010 | X65: 101100000
O66: erode 1 | P66: 468 | Q66: 352 | S66: 0111010100 | X66: 101100000
O67: erode 2 | P67: 510 | Q67: 352 | S67: 0111111110 | X67: 101100000
O68: dilate 1 | P68: 552 | Q68: 352 | S68: 1000101000 | X68: 101100000
O69: dilate 2 | P69: 594 | Q69: 352 | S69: 1001010010 | X69: 101100000
S70: =_xlfn.CONCAT(S64:S69) -> 010100000001100010100111010100011111111010001010001001010010
X71: =_xlfn.CONCAT(X64:X69) -> 101100000101100000101100000101100000101100000101100000
CA132: 2 | CB132: 2 | CC132: 2 | CD132: 2 | CE132: 2 | CF132: 2 | CG132: 2 | CH132: 2 | CI132: 2 | CJ132: 2 | CK132: 2 | CL132: 2 | CM132: 2 | CU132: 2 | CV132: 2 | CW132: 2 | CX132: 2 | CY132: 2 | CZ132: 2 | DA132: 2 | DB132: 2 | DC132: 2 | DD132: 2 | DE132: 2 | DF132: 2 | DJ132: 2 2 2 2 2 2 2 2 2 2 2 2
CA133: 2 | CB133: 2 | CC133: 2 | CD133: 2 | CE133: 2 | CF133: 2 | CG133: 2 | CH133: 2 | CI133: 2 | CJ133: 2 | CK133: 2 | CL133: 2 | CM133: 2 | CU133: 2 | CV133: 1 | CW133: 1 | CX133: 1 | CY133: 1 | CZ133: 1 | DA133: 1 | DB133: 1 | DC133: 1 | DD133: 2 | DE133: 2 | DF133: 2 | DJ133: 2 1 1 1 1 1 1 1 1 2 2 2
CA134: 2 | CB134: 2 | CC134: 2 | CD134: 2 | CE134: 2 | CF134: 2 | CG134: 2 | CH134: 2 | CI134: 2 | CJ134: 2 | CK134: 2 | CL134: 2 | CM134: 2 | CU134: 2 | CV134: 1 | CW134: 1 | CX134: 1 | CY134: 1 | CZ134: 1 | DA134: 1 | DB134: 1 | DC134: 1 | DD134: 2 | DE134: 2 | DF134: 2
CA135: 2 | CB135: 2 | CC135: 2 | CD135: 2 | CE135: 2 | CF135: 2 | CG135: 2 | CH135: 2 | CI135: 2 | CJ135: 2 | CK135: 2 | CL135: 2 | CM135: 2 | CU135: 2 | CV135: 1 | CW135: 1 | CX135: 2 | CY135: 2 | CZ135: 2 | DA135: 2 | DB135: 2 | DC135: 2 | DD135: 1 | DE135: 1 | DF135: 2
CA136: 2 | CB136: 2 | CC136: 2 | CD136: 2 | CE136: 2 | CF136: 2 | CG136: 2 | CH136: 2 | CI136: 2 | CJ136: 2 | CK136: 2 | CL136: 2 | CM136: 2 | CU136: 2 | CV136: 1 | CW136: 1 | CX136: 2 | CY136: 2 | CZ136: 2 | DA136: 2 | DB136: 2 | DC136: 2 | DD136: 1 | DE136: 1 | DF136: 2
CA137: 2 | CB137: 2 | CC137: 2 | CD137: 2 | CE137: 2 | CF137: 2 | CG137: 2 | CH137: 2 | CI137: 2 | CJ137: 2 | CK137: 2 | CL137: 2 | CM137: 2 | CU137: 2 | CV137: 1 | CW137: 1 | CX137: 1 | CY137: 1 | CZ137: 1 | DA137: 1 | DB137: 1 | DC137: 1 | DD137: 2 | DE137: 2 | DF137: 2
CA138: 2 | CB138: 2 | CC138: 2 | CD138: 2 | CE138: 2 | CF138: 2 | CG138: 2 | CH138: 2 | CI138: 2 | CJ138: 2 | CK138: 2 | CL138: 2 | CM138: 2 | CU138: 2 | CV138: 1 | CW138: 1 | CX138: 1 | CY138: 1 | CZ138: 1 | DA138: 1 | DB138: 1 | DC138: 1 | DD138: 2 | DE138: 2 | DF138: 2
CA139: 2 | CB139: 2 | CC139: 2 | CD139: 2 | CE139: 2 | CF139: 2 | CG139: 2 | CH139: 2 | CI139: 2 | CJ139: 2 | CK139: 2 | CL139: 2 | CM139: 2 | CU139: 2 | CV139: 1 | CW139: 1 | CX139: 2 | CY139: 2 | CZ139: 2 | DA139: 2 | DB139: 1 | DC139: 1 | DD139: 2 | DE139: 2 | DF139: 2
CA140: 2 | CB140: 2 | CC140: 2 | CD140: 2 | CE140: 2 | CF140: 2 | CG140: 2 | CH140: 2 | CI140: 2 | CJ140: 2 | CK140: 2 | CL140: 2 | CM140: 2 | CU140: 2 | CV140: 1 | CW140: 1 | CX140: 2 | CY140: 2 | CZ140: 2 | DA140: 2 | DB140: 1 | DC140: 1 | DD140: 2 | DE140: 2 | DF140: 2
CA141: 2 | CB141: 2 | CC141: 2 | CD141: 2 | CE141: 2 | CF141: 2 | CG141: 2 | CH141: 2 | CI141: 2 | CJ141: 2 | CK141: 2 | CL141: 2 | CM141: 2 | CU141: 2 | CV141: 1 | CW141: 1 | CX141: 2 | CY141: 2 | CZ141: 2 | DA141: 2 | DB141: 2 | DC141: 2 | DD141: 1 | DE141: 1 | DF141: 2
CA142: 2 | CB142: 2 | CC142: 2 | CD142: 2 | CE142: 2 | CF142: 2 | CG142: 2 | CH142: 2 | CI142: 2 | CJ142: 2 | CK142: 2 | CL142: 2 | CM142: 2 | CU142: 2 | CV142: 1 | CW142: 1 | CX142: 2 | CY142: 2 | CZ142: 2 | DA142: 2 | DB142: 2 | DC142: 2 | DD142: 1 | DE142: 1 | DF142: 2
CA143: 2 | CB143: 2 | CC143: 2 | CD143: 2 | CE143: 2 | CF143: 2 | CG143: 2 | CH143: 2 | CI143: 2 | CJ143: 2 | CK143: 2 | CL143: 2 | CM143: 2 | CU143: 2 | CV143: 2 | CW143: 2 | CX143: 2 | CY143: 2 | CZ143: 2 | DA143: 2 | DB143: 2 | DC143: 2 | DD143: 2 | DE143: 2 | DF143: 2
CA144: 2 | CB144: 2 | CC144: 2 | CD144: 2 | CE144: 2 | CF144: 2 | CG144: 2 | CH144: 2 | CI144: 2 | CJ144: 2 | CK144: 2 | CL144: 2 | CM144: 2

Sheet modify this
A1: idx | B1: Name | C1: X translated | D1: X | E1: Y | F1: xsize | G1: ysize | I1: rowStart | J1: rowEnd | K1: total | L1: bram counter | N1: exist | O1: actl xsize | P1: actl ysize | Q1: total actl | R1: bram counter 1 | T1: bram offset
A2: 0 | B2: red square | C2: {=COLUMN(INDIRECT(D2 & "1"))} -> 128 | D2: DX | E2: 348 | F2: 12 | G2: 12 | I2: 1 | J2: =I2+G2-1 -> 12 | K2: =F2*G2 -> 144 | L2: 0 | N2: 0 | O2: =IF(NOT($N2), F2, 0) -> 12 | P2: =IF(NOT($N2), G2, 0) -> 12 | Q2: =O2*P2 -> 144 | R2: 0 | T2: =IF(ISBLANK(S2),R2,S2) -> 0
A3: 1 | B3: green square | C3: {=COLUMN(INDIRECT(D3 & "1"))} -> 128 | D3: DX | E3: 363 | F3: 12 | G3: 12 | I3: =J2+1 -> 13 | J3: =I3+P3-1 -> 24 | K3: =F3*G3 -> 144 | L3: =IF(NOT(N3), L2+K2, L2) -> 144 | N3: 0 | O3: =IF(NOT($N3), F3, 0) -> 12 | P3: =IF(NOT($N3), G3, 0) -> 12 | Q3: =O3*P3 -> 144 | R3: =R2+Q2 -> 144 | T3: =IF(ISBLANK(S3),R3,S3) -> 144
A4: 2 | B4: blue square | C4: {=COLUMN(INDIRECT(D4 & "1"))} -> 128 | D4: DX | E4: 378 | F4: 12 | G4: 12 | I4: =J3+1 -> 25 | J4: =I4+P4-1 -> 36 | K4: =F4*G4 -> 144 | L4: =IF(NOT(N4), L3+K3, L3) -> 288 | N4: 0 | O4: =IF(NOT($N4), F4, 0) -> 12 | P4: =IF(NOT($N4), G4, 0) -> 12 | Q4: =O4*P4 -> 144 | R4: =R3+Q3 -> 288 | T4: =IF(ISBLANK(S4),R4,S4) -> 288
A5: 3 | B5: eyedropper | C5: 289 | D5: JW | E5: 330 | F5: 15 | G5: 15 | I5: =J4+1 -> 37 | J5: =I5+P5-1 -> 51 | K5: =F5*G5 -> 225 | L5: =IF(NOT(N5), L4+K4, L4) -> 432 | N5: 0 | O5: =IF(NOT($N5), F5, 0) -> 15 | P5: =IF(NOT($N5), G5, 0) -> 15 | Q5: =O5*P5 -> 225 | R5: =R4+Q4 -> 432 | T5: =IF(ISBLANK(S5),R5,S5) -> 432
A6: 4 | B6: threshold | C6: {=COLUMN(INDIRECT(D6 & "1"))} -> 33 | D6: AG | E6: 330 | F6: 81 | G6: 12 | I6: =J5+1 -> 52 | J6: =I6+P6-1 -> 63 | K6: =F6*G6 -> 972 | L6: =IF(NOT(N6), L5+K5, L5) -> 657 | N6: 0 | O6: =IF(NOT($N6), F6, 0) -> 81 | P6: =IF(NOT($N6), G6, 0) -> 12 | Q6: =O6*P6 -> 972 | R6: =R5+Q5 -> 657 | T6: =IF(ISBLANK(S6),R6,S6) -> 657
A7: 5 | B7: raw feed | C7: {=COLUMN(INDIRECT(D7 & "1"))} -> 39 | D7: AM | E7: 401 | F7: 36 | G7: 29 | I7: =J6+1 -> 64 | J7: =I7+P7-1 -> 92 | K7: =F7*G7 -> 1044 | L7: =IF(NOT(N7), L6+K6, L6) -> 1629 | N7: 0 | O7: =IF(NOT($N7), F7, 0) -> 36 | P7: =IF(NOT($N7), G7, 0) -> 29 | Q7: =O7*P7 -> 1044 | R7: =R6+Q6 -> 1629 | T7: =IF(ISBLANK(S7),R7,S7) -> 1629
A8: 6 | B8: camera | C8: {=COLUMN(INDIRECT(D8 & "1"))} -> 40 | D8: AN | E8: 446 | F8: 34 | G8: 12 | I8: =J7+1 -> 93 | J8: =I8+P8-1 -> 104 | K8: =F8*G8 -> 408 | L8: =IF(NOT(N8), L7+K7, L7) -> 2673 | N8: 0 | O8: =IF(NOT($N8), F8, 0) -> 34 | P8: =IF(NOT($N8), G8, 0) -> 12 | Q8: =O8*P8 -> 408 | R8: =R7+Q7 -> 2673 | T8: =IF(ISBLANK(S8),R8,S8) -> 2673
A9: 7 | B9: preprocessing | C9: {=COLUMN(INDIRECT(D9 & "1"))} -> 124 | D9: DT | E9: 410 | F9: 112 | G9: 18 | I9: =J8+1 -> 105 | J9: =I9+P9-1 -> 122 | K9: =F9*G9 -> 2016 | L9: =IF(NOT(N9), L8+K8, L8) -> 3081 | N9: 0 | O9: =IF(NOT($N9), F9, 0) -> 112 | P9: =IF(NOT($N9), G9, 0) -> 18 | Q9: =O9*P9 -> 2016 | R9: =R8+Q8 -> 3081 | T9: =IF(ISBLANK(S9),R9,S9) -> 3081
A10: 8 | B10: yellow arrow | C10: {=COLUMN(INDIRECT(D10 & "1"))} -> 80 | D10: CB | E10: 448 | F10: 25 | G10: 8 | I10: =J9+1 -> 123 | J10: =I10+P10-1 -> 130 | K10: =F10*G10 -> 200 | L10: =IF(NOT(N10), L9+K9, L9) -> 5097 | N10: 0 | O10: =IF(NOT($N10), F10, 0) -> 25 | P10: =IF(NOT($N10), G10, 0) -> 8 | Q10: =O10*P10 -> 200 | R10: =R9+Q9 -> 5097 | T10: =IF(ISBLANK(S10),R10,S10) -> 5097
A11: 9 | B11: yellow arrow 2 | C11: {=COLUMN(INDIRECT(D11 & "1"))} -> 253 | D11: IS | E11: 448 | F11: 25 | G11: 8 | I11: =J10+1 -> 131 | J11: =I11+P11-1 -> 130 | K11: =F11*G11 -> 200 | L11: =IF(NOT(N11), L10+K10, L10) -> 5097 | N11: 1 | O11: =IF(NOT($N11), F11, 0) -> 0 | P11: =IF(NOT($N11), G11, 0) -> 0 | Q11: =O11*P11 -> 0 | R11: =R10+Q10 -> 5297 | S11: =R10 -> 5097 | T11: =IF(ISBLANK(S11),R11,S11) -> 5097
A12: 10 | B12: yellow arrow 3 | C12: {=COLUMN(INDIRECT(D12 & "1"))} -> 350 | D12: ML | E12: 448 | F12: 25 | G12: 8 | I12: =J11+1 -> 131 | J12: =I12+P12-1 -> 130 | K12: =F12*G12 -> 200 | L12: =IF(NOT(N12), L11+K11, L11) -> 5097 | N12: 1 | O12: =IF(NOT($N12), F12, 0) -> 0 | P12: =IF(NOT($N12), G12, 0) -> 0 | Q12: =O12*P12 -> 0 | R12: =R11+Q11 -> 5297 | S12: =R10 -> 5097 | T12: =IF(ISBLANK(S12),R12,S12) -> 5097
A13: 11 | B13: yellow arrow 4 | C13: {=COLUMN(INDIRECT(D13 & "1"))} -> 539 | D13: TS | E13: 448 | F13: 25 | G13: 8 | I13: =J12+1 -> 131 | J13: =I13+P13-1 -> 130 | K13: =F13*G13 -> 200 | L13: =IF(NOT(N13), L12+K12, L12) -> 5097 | N13: 1 | O13: =IF(NOT($N13), F13, 0) -> 0 | P13: =IF(NOT($N13), G13, 0) -> 0 | Q13: =O13*P13 -> 0 | R13: =R12+Q12 -> 5297 | S13: =R10 -> 5097 | T13: =IF(ISBLANK(S13),R13,S13) -> 5097
A14: 12 | B14: yellow rect short | C14: {=COLUMN(INDIRECT(D14 & "1"))} -> 106 | D14: DB | E14: 451 | F14: 146 | G14: 2 | I14: =J13+1 -> 131 | J14: =I14+P14-1 -> 130 | K14: =F14*G14 -> 292 | L14: =IF(NOT(N14), L13+K13, L13) -> 5097 | N14: 1 | O14: =IF(NOT($N14), F14, 0) -> 0 | P14: =IF(NOT($N14), G14, 0) -> 0 | Q14: =O14*P14 -> 0 | R14: =R13+Q13 -> 5297 | S14: =R15 -> 5297 | T14: =IF(ISBLANK(S14),R14,S14) -> 5297
A15: 13 | B15: yellow rect long | C15: {=COLUMN(INDIRECT(D15 & "1"))} -> 376 | D15: NL | E15: 451 | F15: 162 | G15: 2 | I15: =J14+1 -> 131 | J15: =I15+P15-1 -> 132 | K15: =F15*G15 -> 324 | L15: =IF(NOT(N15), L14+K14, L14) -> 5389 | N15: 0 | O15: =IF(NOT($N15), F15, 0) -> 162 | P15: =IF(NOT($N15), G15, 0) -> 2 | Q15: =O15*P15 -> 324 | R15: =R14+Q14 -> 5297 | T15: =IF(ISBLANK(S15),R15,S15) -> 5297
A16: 14 | B16: open eye | C16: {=COLUMN(INDIRECT(D16 & "1"))} -> 85 | D16: CG | E16: 435 | F16: 15 | G16: 12 | I16: =J15+1 -> 133 | J16: =I16+P16-1 -> 144 | K16: =F16*G16 -> 180 | L16: =IF(NOT(N16), L15+K15, L15) -> 5713 | N16: 0 | O16: =IF(NOT($N16), F16, 0) -> 15 | P16: =IF(NOT($N16), G16, 0) -> 12 | Q16: =O16*P16 -> 180 | R16: =R15+Q15 -> 5621 | T16: =IF(ISBLANK(S16),R16,S16) -> 5621
A17: 15 | B17: eye1 | C17: {=COLUMN(INDIRECT(D17 & "1"))} -> 258 | D17: IX | E17: 435 | F17: 15 | G17: 12 | I17: =J16+1 -> 145 | J17: =I17+P17-1 -> 156 | K17: =F17*G17 -> 180 | L17: =IF(NOT(N17), L16+K16, L16) -> 5893 | N17: 0 | O17: =IF(NOT($N17), F17, 0) -> 15 | P17: =IF(NOT($N17), G17, 0) -> 12 | Q17: =O17*P17 -> 180 | R17: =R16+Q16 -> 5801 | T17: =IF(ISBLANK(S17),R17,S17) -> 5801
A18: 16 | B18: eye2 | C18: {=COLUMN(INDIRECT(D18 & "1"))} -> 355 | D18: MQ | E18: 435 | F18: 15 | G18: 12 | I18: =J17+1 -> 157 | J18: =I18+P18-1 -> 156 | K18: =F18*G18 -> 180 | L18: =IF(NOT(N18), L17+K17, L17) -> 5893 | N18: 1 | O18: =IF(NOT($N18), F18, 0) -> 0 | P18: =IF(NOT($N18), G18, 0) -> 0 | Q18: =O18*P18 -> 0 | R18: =R17+Q17 -> 5981 | S18: =R17 -> 5801 | T18: =IF(ISBLANK(S18),R18,S18) -> 5801
A19: 17 | B19: eye3 | C19: {=COLUMN(INDIRECT(D19 & "1"))} -> 544 | D19: TX | E19: 435 | F19: 15 | G19: 12 | I19: =J18+1 -> 157 | J19: =I19+P19-1 -> 156 | K19: =F19*G19 -> 180 | L19: =IF(NOT(N19), L18+K18, L18) -> 5893 | N19: 1 | O19: =IF(NOT($N19), F19, 0) -> 0 | P19: =IF(NOT($N19), G19, 0) -> 0 | Q19: =O19*P19 -> 0 | R19: =R18+Q18 -> 5981 | S19: =R17 -> 5801 | T19: =IF(ISBLANK(S19),R19,S19) -> 5801
A20: 18 | B20: thresholding | C20: {=COLUMN(INDIRECT(D20 & "1"))} -> 262 | D20: JB | E20: 410 | F20: 105 | G20: 18 | I20: =J19+1 -> 157 | J20: =I20+P20-1 -> 174 | K20: =F20*G20 -> 1890 | L20: =IF(NOT(N20), L19+K19, L19) -> 6073 | N20: 0 | O20: =IF(NOT($N20), F20, 0) -> 105 | P20: =IF(NOT($N20), G20, 0) -> 18 | Q20: =O20*P20 -> 1890 | R20: =R19+Q19 -> 5981 | T20: =IF(ISBLANK(S20),R20,S20) -> 5981
A21: 19 | B21: bitmap | C21: {=COLUMN(INDIRECT(D21 & "1"))} -> 282 | D21: JV | E21: 446 | F21: 64 | G21: 12 | I21: =J20+1 -> 175 | J21: =I21+P21-1 -> 186 | K21: =F21*G21 -> 768 | L21: =IF(NOT(N21), L20+K20, L20) -> 7963 | N21: 0 | O21: =IF(NOT($N21), F21, 0) -> 64 | P21: =IF(NOT($N21), G21, 0) -> 12 | Q21: =O21*P21 -> 768 | R21: =R20+Q20 -> 7871 | T21: =IF(ISBLANK(S21),R21,S21) -> 7871
A22: 20 | B22: morphology | C22: {=COLUMN(INDIRECT(D22 & "1"))} -> 410 | D22: OT | E22: 410 | F22: 95 | G22: 18 | I22: =J21+1 -> 187 | J22: =I22+P22-1 -> 204 | K22: =F22*G22 -> 1710 | L22: =IF(NOT(N22), L21+K21, L21) -> 8731 | N22: 0 | O22: =IF(NOT($N22), F22, 0) -> 95 | P22: =IF(NOT($N22), G22, 0) -> 18 | Q22: =O22*P22 -> 1710 | R22: =R21+Q21 -> 8639 | T22: =IF(ISBLANK(S22),R22,S22) -> 8639
A23: 21 | B23: obj detection | C23: {=COLUMN(INDIRECT(D23 & "1"))} -> 558 | D23: UL | E23: 401 | F23: 77 | G23: 29 | I23: =J22+1 -> 205 | J23: =I23+P23-1 -> 233 | K23: =F23*G23 -> 2233 | L23: =IF(NOT(N23), L22+K22, L22) -> 10441 | N23: 0 | O23: =IF(NOT($N23), F23, 0) -> 77 | P23: =IF(NOT($N23), G23, 0) -> 29 | Q23: =O23*P23 -> 2233 | R23: =R22+Q22 -> 10349 | T23: =IF(ISBLANK(S23),R23,S23) -> 10349
A24: 22 | B24: ufds | C24: {=COLUMN(INDIRECT(D24 & "1"))} -> 578 | D24: VF | E24: 446 | F24: 38 | G24: 12 | I24: =J23+1 -> 234 | J24: =I24+P24-1 -> 245 | K24: =F24*G24 -> 456 | L24: =IF(NOT(N24), L23+K23, L23) -> 12674 | N24: 0 | O24: =IF(NOT($N24), F24, 0) -> 38 | P24: =IF(NOT($N24), G24, 0) -> 12 | Q24: =O24*P24 -> 456 | R24: =R23+Q23 -> 12582 | T24: =IF(ISBLANK(S24),R24,S24) -> 12582
A25: 23 | B25: image processing | C25: {=COLUMN(INDIRECT(D25 & "1"))} -> 320 | D25: LH | E25: 330 | F25: 196 | G25: 18 | I25: =J24+1 -> 246 | J25: =I25+P25-1 -> 263 | K25: =F25*G25 -> 3528 | L25: =IF(NOT(N25), L24+K24, L24) -> 13130 | N25: 0 | O25: =IF(NOT($N25), F25, 0) -> 196 | P25: =IF(NOT($N25), G25, 0) -> 18 | Q25: =O25*P25 -> 3528 | R25: =R24+Q24 -> 13038 | T25: =IF(ISBLANK(S25),R25,S25) -> 13038
A26: 24 | B26: gaussian edu tab | C26: {=COLUMN(INDIRECT(D26 & "1"))} -> 362 | D26: MX | E26: 296 | F26: 281 | G26: 27 | I26: =J25+1 -> 264 | J26: =I26+P26-1 -> 290 | K26: =F26*G26 -> 7587 | L26: =IF(NOT(N26), L25+K25, L25) -> 16658 | N26: 0 | O26: =IF(NOT($N26), F26, 0) -> 281 | P26: =IF(NOT($N26), G26, 0) -> 27 | Q26: =O26*P26 -> 7587 | R26: =R25+Q25 -> 16566 | T26: =IF(ISBLANK(S26),R26,S26) -> 16566
B27: median edu tab??? | C27: {=COLUMN(INDIRECT(D27 & "1"))} -> #REF! | I27: =J26+1 -> 291 | J27: =I27+P27-1 -> 290 | K27: =F27*G27 -> 0 | L27: =IF(NOT(N27), L26+K26, L26) -> 24245 | N27: 0 | O27: =IF(NOT($N27), F27, 0) -> 0 | P27: =IF(NOT($N27), G27, 0) -> 0 | Q27: =O27*P27 -> 0 | R27: =R26+Q26 -> 24153 | T27: =IF(ISBLANK(S27),R27,S27) -> 24153
A28: 25 | B28: Object | C28: {=COLUMN(INDIRECT(D28 & "1"))} -> 34 | D28: AH | E28: 301 | F28: 52 | G28: 18 | H28: AG | I28: =J27+1 -> 291 | J28: =I28+P28-1 -> 308 | K28: =F28*G28 -> 936 | L28: =IF(NOT(N28), L27+K27, L27) -> 24245 | N28: 0 | O28: =IF(NOT($N28), F28, 0) -> 52 | P28: =IF(NOT($N28), G28, 0) -> 18 | Q28: =O28*P28 -> 936 | R28: =R27+Q27 -> 24153 | T28: =IF(ISBLANK(S28),R28,S28) -> 24153
A29: 26 | B29: Det Union Find | C29: {=COLUMN(INDIRECT(D29 & "1"))} -> 88 | D29: CJ | E29: 301 | F29: 169 | G29: 12 | H29: CI | I29: =J28+1 -> 309 | J29: =I29+P29-1 -> 320 | K29: =F29*G29 -> 2028 | L29: =IF(NOT(N29), L28+K28, L28) -> 25181 | N29: 0 | O29: =IF(NOT($N29), F29, 0) -> 169 | P29: =IF(NOT($N29), G29, 0) -> 12 | Q29: =O29*P29 -> 2028 | R29: =R28+Q28 -> 25089 | T29: =IF(ISBLANK(S29),R29,S29) -> 25089
A30: 27 | B30: Disjoint | C30: {=COLUMN(INDIRECT(D30 & "1"))} -> 259 | D30: IY | E30: 301 | F30: 60 | G30: 18 | H30: IX | I30: =J29+1 -> 321 | J30: =I30+P30-1 -> 338 | K30: =F30*G30 -> 1080 | L30: =IF(NOT(N30), L29+K29, L29) -> 27209 | N30: 0 | O30: =IF(NOT($N30), F30, 0) -> 60 | P30: =IF(NOT($N30), G30, 0) -> 18 | Q30: =O30*P30 -> 1080 | R30: =R29+Q29 -> 27117 | T30: =IF(ISBLANK(S30),R30,S30) -> 27117
A31: 28 | B31: Set | C31: {=COLUMN(INDIRECT(D31 & "1"))} -> 321 | D31: LI | E31: 301 | F31: 26 | G31: 12 | H31: LH | I31: =J30+1 -> 339 | J31: =I31+P31-1 -> 350 | K31: =F31*G31 -> 312 | L31: =IF(NOT(N31), L30+K30, L30) -> 28289 | N31: 0 | O31: =IF(NOT($N31), F31, 0) -> 26 | P31: =IF(NOT($N31), G31, 0) -> 12 | Q31: =O31*P31 -> 312 | R31: =R30+Q30 -> 28197 | T31: =IF(ISBLANK(S31),R31,S31) -> 28197
A32: 29 | B32: Post | C32: {=COLUMN(INDIRECT(D32 & "1"))} -> 25 | D32: Y | E32: 379 | F32: 35 | G32: 12 | H32: X | I32: =J31+1 -> 351 | J32: =I32+P32-1 -> 362 | K32: =F32*G32 -> 420 | L32: =IF(NOT(N32), L31+K31, L31) -> 28601 | N32: 0 | O32: =IF(NOT($N32), F32, 0) -> 35 | P32: =IF(NOT($N32), G32, 0) -> 12 | Q32: =O32*P32 -> 420 | R32: =R31+Q31 -> 28509 | T32: =IF(ISBLANK(S32),R32,S32) -> 28509
A33: 30 | B33: Feed | C33: {=COLUMN(INDIRECT(D33 & "1"))} -> 25 | D33: Y | E33: 393 | F33: 36 | G33: 12 | H33: X | I33: =J32+1 -> 363 | J33: =I33+P33-1 -> 374 | K33: =F33*G33 -> 432 | L33: =IF(NOT(N33), L32+K32, L32) -> 29021 | N33: 0 | O33: =IF(NOT($N33), F33, 0) -> 36 | P33: =IF(NOT($N33), G33, 0) -> 12 | Q33: =O33*P33 -> 432 | R33: =R32+Q32 -> 28929 | T33: =IF(ISBLANK(S33),R33,S33) -> 28929
A34: 31 | B34: open eye 4 | C34: {=COLUMN(INDIRECT(D34 & "1"))} -> 37 | D34: AK | E34: 435 | F34: 15 | G34: 12 | H34: AJ | I34: =J33+1 -> 375 | J34: =I34+P34-1 -> 374 | K34: =F34*G34 -> 180 | L34: =IF(NOT(N34), L33+K33, L33) -> 29021 | N34: 1 | O34: =IF(NOT($N34), F34, 0) -> 0 | P34: =IF(NOT($N34), G34, 0) -> 0 | Q34: =O34*P34 -> 0 | R34: =R33+Q33 -> 29361 | S34: =R16 -> 5621 | T34: =IF(ISBLANK(S34),R34,S34) -> 5621
A35: 32 | B35: yellow arrow 5 | C35: {=COLUMN(INDIRECT(D35 & "1"))} -> 33 | D35: AG | E35: 448 | F35: 25 | G35: 8 | H35: AF | I35: =J34+1 -> 375 | J35: =I35+P35-1 -> 374 | K35: =F35*G35 -> 200 | L35: =IF(NOT(N35), L34+K34, L34) -> 29021 | N35: 1 | O35: =IF(NOT($N35), F35, 0) -> 0 | P35: =IF(NOT($N35), G35, 0) -> 0 | Q35: =O35*P35 -> 0 | R35: =R34+Q34 -> 29361 | S35: =R10 -> 5097 | T35: =IF(ISBLANK(S35),R35,S35) -> 5097
A36: 33 | B36: Ready | C36: {=COLUMN(INDIRECT(D36 & "1"))} -> 63 | D36: BK | E36: 444 | F36: 49 | G36: 12 | H36: BJ | I36: =J35+1 -> 375 | J36: =I36+P36-1 -> 386 | K36: =F36*G36 -> 588 | L36: =IF(NOT(N36), L35+K35, L35) -> 29221 | N36: 0 | O36: =IF(NOT($N36), F36, 0) -> 49 | P36: =IF(NOT($N36), G36, 0) -> 12 | Q36: =O36*P36 -> 588 | R36: =R35+Q35 -> 29361 | T36: =IF(ISBLANK(S36),R36,S36) -> 29361
A37: 34 | B37: Up→right | C37: {=COLUMN(INDIRECT(D37 & "1"))} -> 78 | D37: BZ | E37: 375 | F37: 4 | G37: 4 | H37: BY | I37: =J36+1 -> 387 | J37: =I37+P37-1 -> 390 | K37: =F37*G37 -> 16 | L37: =IF(NOT(N37), L36+K36, L36) -> 29809 | N37: 0 | O37: =IF(NOT($N37), F37, 0) -> 4 | P37: =IF(NOT($N37), G37, 0) -> 4 | Q37: =O37*P37 -> 16 | R37: =R36+Q36 -> 29949 | T37: =IF(ISBLANK(S37),R37,S37) -> 29949
A38: 35 | B38: Sample neighbour | C38: {=COLUMN(INDIRECT(D38 & "1"))} -> 70 | D38: BR | E38: 331 | F38: 146 | G38: 18 | H38: BQ | I38: =J37+1 -> 391 | J38: =I38+P38-1 -> 408 | K38: =F38*G38 -> 2628 | L38: =IF(NOT(N38), L37+K37, L37) -> 29825 | N38: 0 | O38: =IF(NOT($N38), F38, 0) -> 146 | P38: =IF(NOT($N38), G38, 0) -> 18 | Q38: =O38*P38 -> 2628 | R38: =R37+Q37 -> 29965 | T38: =IF(ISBLANK(S38),R38,S38) -> 29965
A39: 36 | B39: Findroots | C39: {=COLUMN(INDIRECT(D39 & "1"))} -> 101 | D39: CW | E39: 353 | F39: 83 | G39: 12 | H39: CV | I39: =J38+1 -> 409 | J39: =I39+P39-1 -> 420 | K39: =F39*G39 -> 996 | L39: =IF(NOT(N39), L38+K38, L38) -> 32453 | N39: 0 | O39: =IF(NOT($N39), F39, 0) -> 83 | P39: =IF(NOT($N39), G39, 0) -> 12 | Q39: =O39*P39 -> 996 | R39: =R38+Q38 -> 32593 | T39: =IF(ISBLANK(S39),R39,S39) -> 32593
A40: 37 | B40: small arrow | C40: {=COLUMN(INDIRECT(D40 & "1"))} -> 82 | D40: CD | E40: 372 | F40: 13 | G40: 10 | H40: CC | I40: =J39+1 -> 421 | J40: =I40+P40-1 -> 430 | K40: =F40*G40 -> 130 | L40: =IF(NOT(N40), L39+K39, L39) -> 33449 | N40: 0 | O40: =IF(NOT($N40), F40, 0) -> 13 | P40: =IF(NOT($N40), G40, 0) -> 10 | Q40: =O40*P40 -> 130 | R40: =R39+Q39 -> 33589 | T40: =IF(ISBLANK(S40),R40,S40) -> 33589
...

Sheet only read from this
A1: ='modify this'!A1 -> idx | B1: ='modify this'!B1 -> Name | C1: ='modify this'!C1 -> X translated | D1: ='modify this'!E1 -> Y | E1: ='modify this'!F1 -> xsize | F1: ='modify this'!G1 -> ysize | G1: ='modify this'!T1 -> bram offset
A2: ='modify this'!A2 -> 0 | B2: ='modify this'!B2 -> red square | C2: ='modify this'!C2 -> 128 | D2: ='modify this'!E2 -> 348 | E2: ='modify this'!F2 -> 12 | F2: ='modify this'!G2 -> 12 | G2: ='modify this'!T2 -> 0 | J2: =_xlfn.CONCAT(C2, ", ", D2, ", ", E2, ", ", F2, ", ", G2, ", ") -> 128, 348, 12, 12, 0, | K2: =_xlfn.CONCAT("// ", A2, " ", B2) -> // 0 red square
A3: ='modify this'!A3 -> 1 | B3: ='modify this'!B3 -> green square | C3: ='modify this'!C3 -> 128 | D3: ='modify this'!E3 -> 363 | E3: ='modify this'!F3 -> 12 | F3: ='modify this'!G3 -> 12 | G3: ='modify this'!T3 -> 144 | J3: =_xlfn.CONCAT(C3, ", ", D3, ", ", E3, ", ", F3, ", ", G3, ", ") -> 128, 363, 12, 12, 144, | K3: =_xlfn.CONCAT("// ", A3, " ", B3) -> // 1 green square
A4: ='modify this'!A4 -> 2 | B4: ='modify this'!B4 -> blue square | C4: ='modify this'!C4 -> 128 | D4: ='modify this'!E4 -> 378 | E4: ='modify this'!F4 -> 12 | F4: ='modify this'!G4 -> 12 | G4: ='modify this'!T4 -> 288 | J4: =_xlfn.CONCAT(C4, ", ", D4, ", ", E4, ", ", F4, ", ", G4, ", ") -> 128, 378, 12, 12, 288, | K4: =_xlfn.CONCAT("// ", A4, " ", B4) -> // 2 blue square
A5: ='modify this'!A5 -> 3 | B5: ='modify this'!B5 -> eyedropper | C5: ='modify this'!C5 -> 289 | D5: ='modify this'!E5 -> 330 | E5: ='modify this'!F5 -> 15 | F5: ='modify this'!G5 -> 15 | G5: ='modify this'!T5 -> 432 | J5: =_xlfn.CONCAT(C5, ", ", D5, ", ", E5, ", ", F5, ", ", G5, ", ") -> 289, 330, 15, 15, 432, | K5: =_xlfn.CONCAT("// ", A5, " ", B5) -> // 3 eyedropper
A6: ='modify this'!A6 -> 4 | B6: ='modify this'!B6 -> threshold | C6: ='modify this'!C6 -> 33 | D6: ='modify this'!E6 -> 330 | E6: ='modify this'!F6 -> 81 | F6: ='modify this'!G6 -> 12 | G6: ='modify this'!T6 -> 657 | J6: =_xlfn.CONCAT(C6, ", ", D6, ", ", E6, ", ", F6, ", ", G6, ", ") -> 33, 330, 81, 12, 657, | K6: =_xlfn.CONCAT("// ", A6, " ", B6) -> // 4 threshold
A7: ='modify this'!A7 -> 5 | B7: ='modify this'!B7 -> raw feed | C7: ='modify this'!C7 -> 39 | D7: ='modify this'!E7 -> 401 | E7: ='modify this'!F7 -> 36 | F7: ='modify this'!G7 -> 29 | G7: ='modify this'!T7 -> 1629 | J7: =_xlfn.CONCAT(C7, ", ", D7, ", ", E7, ", ", F7, ", ", G7, ", ") -> 39, 401, 36, 29, 1629, | K7: =_xlfn.CONCAT("// ", A7, " ", B7) -> // 5 raw feed
A8: ='modify this'!A8 -> 6 | B8: ='modify this'!B8 -> camera | C8: ='modify this'!C8 -> 40 | D8: ='modify this'!E8 -> 446 | E8: ='modify this'!F8 -> 34 | F8: ='modify this'!G8 -> 12 | G8: ='modify this'!T8 -> 2673 | J8: =_xlfn.CONCAT(C8, ", ", D8, ", ", E8, ", ", F8, ", ", G8, ", ") -> 40, 446, 34, 12, 2673, | K8: =_xlfn.CONCAT("// ", A8, " ", B8) -> // 6 camera
A9: ='modify this'!A9 -> 7 | B9: ='modify this'!B9 -> preprocessing | C9: ='modify this'!C9 -> 124 | D9: ='modify this'!E9 -> 410 | E9: ='modify this'!F9 -> 112 | F9: ='modify this'!G9 -> 18 | G9: ='modify this'!T9 -> 3081 | J9: =_xlfn.CONCAT(C9, ", ", D9, ", ", E9, ", ", F9, ", ", G9, ", ") -> 124, 410, 112, 18, 3081, | K9: =_xlfn.CONCAT("// ", A9, " ", B9) -> // 7 preprocessing
A10: ='modify this'!A10 -> 8 | B10: ='modify this'!B10 -> yellow arrow | C10: ='modify this'!C10 -> 80 | D10: ='modify this'!E10 -> 448 | E10: ='modify this'!F10 -> 25 | F10: ='modify this'!G10 -> 8 | G10: ='modify this'!T10 -> 5097 | J10: =_xlfn.CONCAT(C10, ", ", D10, ", ", E10, ", ", F10, ", ", G10, ", ") -> 80, 448, 25, 8, 5097, | K10: =_xlfn.CONCAT("// ", A10, " ", B10) -> // 8 yellow arrow
A11: ='modify this'!A11 -> 9 | B11: ='modify this'!B11 -> yellow arrow 2 | C11: ='modify this'!C11 -> 253 | D11: ='modify this'!E11 -> 448 | E11: ='modify this'!F11 -> 25 | F11: ='modify this'!G11 -> 8 | G11: ='modify this'!T11 -> 5097 | J11: =_xlfn.CONCAT(C11, ", ", D11, ", ", E11, ", ", F11, ", ", G11, ", ") -> 253, 448, 25, 8, 5097, | K11: =_xlfn.CONCAT("// ", A11, " ", B11) -> // 9 yellow arrow 2
A12: ='modify this'!A12 -> 10 | B12: ='modify this'!B12 -> yellow arrow 3 | C12: ='modify this'!C12 -> 350 | D12: ='modify this'!E12 -> 448 | E12: ='modify this'!F12 -> 25 | F12: ='modify this'!G12 -> 8 | G12: ='modify this'!T12 -> 5097 | J12: =_xlfn.CONCAT(C12, ", ", D12, ", ", E12, ", ", F12, ", ", G12, ", ") -> 350, 448, 25, 8, 5097, | K12: =_xlfn.CONCAT("// ", A12, " ", B12) -> // 10 yellow arrow 3
A13: ='modify this'!A13 -> 11 | B13: ='modify this'!B13 -> yellow arrow 4 | C13: ='modify this'!C13 -> 539 | D13: ='modify this'!E13 -> 448 | E13: ='modify this'!F13 -> 25 | F13: ='modify this'!G13 -> 8 | G13: ='modify this'!T13 -> 5097 | J13: =_xlfn.CONCAT(C13, ", ", D13, ", ", E13, ", ", F13, ", ", G13, ", ") -> 539, 448, 25, 8, 5097, | K13: =_xlfn.CONCAT("// ", A13, " ", B13) -> // 11 yellow arrow 4
... A131: ='modify this'!A131 -> 128 | B131: ='modify this'!B131 -> ?? Anything new | C131: ='modify this'!C131 -> #REF! | D131: ='modify this'!E131 -> 0 | E131: ='modify this'!F131 -> 0 | F131: ='modify this'!G131 -> 0 | G131: ='modify this'!T131 -> 123508 | J131: =_xlfn.CONCAT(C131, ", ", D131, ", ", E131, ", ", F131, ", ", G131, ", ") -> #REF! | K131: =_xlfn.CONCAT("// ", A131, " ", B131) -> // 128 ?? Anything new
A132: ='modify this'!A132 -> 0 | B132: ='modify this'!B132 -> 0 | D132: ='modify this'!E132 -> 0 | E132: ='modify this'!F132 -> 0 | F132: ='modify this'!G132 -> 0 | G132: ='modify this'!T132 -> 0 | J132: =_xlfn.CONCAT(C132, ", ", D132, ", ", E132, ", ", F132, ", ", G132, ", ") -> , 0, 0, 0, 0, | K132: =_xlfn.CONCAT("// ", A132, " ", B132) -> // 0 0
A133: ='modify this'!A133 -> 0 | B133: ='modify this'!B133 -> 0 | D133: ='modify this'!E133 -> 0 | E133: ='modify this'!F133 -> 0 | F133: ='modify this'!G133 -> 0 | G133: ='modify this'!T133 -> 0 | J133: =_xlfn.CONCAT(C133, ", ", D133, ", ", E133, ", ", F133, ", ", G133, ", ") -> , 0, 0, 0, 0, | K133: =_xlfn.CONCAT("// ", A133, " ", B133) -> // 0 0
A134: ='modify this'!A134 -> 0 | B134: ='modify this'!B134 -> 0 | D134: ='modify this'!E134 -> 0 | E134: ='modify this'!F134 -> 0 | F134: ='modify this'!G134 -> 0 | G134: ='modify this'!T134 -> 0 | J134: =_xlfn.CONCAT(C134, ", ", D134, ", ", E134, ", ", F134, ", ", G134, ", ") -> , 0, 0, 0, 0, | K134: =_xlfn.CONCAT("// ", A134, " ", B134) -> // 0 0
A135: ='modify this'!A135 -> 0 | B135: ='modify this'!B135 -> 0 | D135: ='modify this'!E135 -> 0 | E135: ='modify this'!F135 -> 0 | F135: ='modify this'!G135 -> 0 | G135: ='modify this'!T135 -> 0
A136: ='modify this'!A136 -> 0 | B136: ='modify this'!B136 -> 0 | D136: ='modify this'!E136 -> 0 | E136: ='modify this'!F136 -> 0 | F136: ='modify this'!G136 -> 0 | G136: ='modify this'!T136 -> 0
A137: ='modify this'!A137 -> 0 | B137: ='modify this'!B137 -> Y relative | D137: ='modify this'!E137 -> (input this in vsc) | E137: ='modify this'!F137 -> 0 | F137: ='modify this'!G137 -> 0 | G137: ='modify this'!T137 -> 0
A138: ='modify this'!A138 -> 0 | B138: ='modify this'!B138 -> Y test | D138: ='modify this'!E138 -> (use this for text) | E138: ='modify this'!F138 -> 0 | F138: ='modify this'!G138 -> 0 | G138: ='modify this'!T138 -> 0
A139: ='modify this'!A139 -> 0 | B139: ='modify this'!B139 -> Y offset | D139: ='modify this'!E139 -> (do not change) | E139: ='modify this'!F139 -> 0 | F139: ='modify this'!G139 -> 0 | G139: ='modify this'!T139 -> 0
B140: ='modify this'!B140 -> X relative | D140: ='modify this'!E140 -> (for text only) | E140: ='modify this'!F140 -> 0 | F140: ='modify this'!G140 -> 0 | G140: ='modify this'!T140 -> 0
